<?xml version="1.0" ?>
<!-- =================================================================================== -->
<!-- |    This document was autogenerated by xacro from model.urdf.xacro               | -->
<!-- |    EDITING THIS FILE BY HAND IS NOT RECOMMENDED                                 | -->
<!-- =================================================================================== -->
<robot name="jungkat">
  <!-- Base link -->
  <link name="base_link">
    <inertial>
      <mass value="5.0"/>
      <inertia ixx="0.1" ixy="0" ixz="0" iyy="0.1" iyz="0" izz="0.1"/>
    </inertial>
    <visual>
      <origin rpy="0 0 0" xyz="0 0 0"/>
      <geometry>
        <box size="0.2 0.2 0.1"/>
      </geometry>
      <material name="gray">
        <color rgba="0.5 0.5 0.5 1"/>
      </material>
    </visual>
  </link>
  <!-- Beam -->
  <link name="beam">
    <inertial>
      <mass value="1.0"/>
      <inertia ixx="0.02" ixy="0" ixz="0" iyy="0.02" iyz="0" izz="0.02"/>
    </inertial>
    <visual>
      <origin rpy="0.2 0 0" xyz="0 0 0"/>
      <!-- Miring sedikit -->
      <geometry>
        <box size="2 0.1 0.1"/>
      </geometry>
      <material name="blue">
        <color rgba="0 0 1 1"/>
      </material>
    </visual>
  </link>
  <!-- Joint -->
  <joint name="pivot_joint" type="revolute">
    <parent link="base_link"/>
    <child link="beam"/>
    <origin rpy="0 0 0" xyz="0 0 0.05"/>
    <axis xyz="0 1 0"/>
    <limit effort="10" lower="-1.57" upper="1.57" velocity="5"/>
    <dynamics damping="0.01" friction="0.01"/>
  </joint>
</robot>

